<sdf version='1.6'>
  <model name='iRobot'>
    <link name='base_link'>
      <pose frame=''>0 0 0 0 -0 0</pose>
      <inertial>
        <pose frame=''>-0.009097 0 0.022727 0 -0 0</pose>
        <mass>11.0032</mass>
        <inertia>
          <ixx>0.217388</ixx>
          <ixy>1.05879e-22</ixy>
          <ixz>0.0227331</ixz>
          <iyy>0.226449</iyy>
          <iyz>-3.36272e-19</iyz>
          <izz>0.298143</izz>
        </inertia>
      </inertial>
      <collision name='base_link_collision'>
        <pose frame=''>0 0 0 0 -0 0</pose>
        <geometry>
          <cylinder>
            <length>0.08</length>
            <radius>0.17</radius>
          </cylinder>
        </geometry>
        <surface>
          <contact>
            <ode/>
          </contact>
          <friction>
            <ode/>
          </friction>
        </surface>
      </collision>
      <collision name='base_link_fixed_joint_lump__left_axis_collision_1'>
        <pose frame=''>0 0.14 -0.02 -1.5708 0 0</pose>
        <geometry>
          <cylinder>
            <length>0.02</length>
            <radius>0.0025</radius>
          </cylinder>
        </geometry>
      </collision>
      <collision name='base_link_fixed_joint_lump__right_axis_collision_2'>
        <pose frame=''>0 -0.14 -0.02 -1.5708 0 0</pose>
        <geometry>
          <cylinder>
            <length>0.02</length>
            <radius>0.0025</radius>
          </cylinder>
        </geometry>
      </collision>
      <collision name='base_link_fixed_joint_lump__box_collision_3'>
        <pose frame=''>-0.1 0 0.25 0 -0 0</pose>
        <geometry>
          <box>
            <size>0.01 0.01 0.5</size>
          </box>
        </geometry>
      </collision>
      <collision name='base_link_fixed_joint_lump__camera_link_collision_4'>
        <pose frame=''>0.08 0 0.1 0 -0 0</pose>
        <geometry>
          <box>
            <size>0.02 0.08 0.11</size>
          </box>
        </geometry>
        <surface>
          <contact>
            <ode/>
          </contact>
          <friction>
            <ode/>
          </friction>
        </surface>
      </collision>
      <collision name='base_link_fixed_joint_lump__camera_up_link_collision_5'>
        <pose frame=''>-0.08 0 0.5 0 1.4 0</pose>
        <geometry>
          <box>
            <size>0.02 0.05 0.05</size>
          </box>
        </geometry>
        <surface>
          <contact>
            <ode/>
          </contact>
          <friction>
            <ode/>
          </friction>
        </surface>
      </collision>
      <collision name='base_link_fixed_joint_lump__hokuyo_link_collision_6'>
        <pose frame=''>0.08 0.09 0.1 0 -0.1 3.11</pose>
        <geometry>
          <cylinder>
            <length>0.12</length>
            <radius>0.015</radius>
          </cylinder>
        </geometry>
        <surface>
          <contact>
            <ode/>
          </contact>
          <friction>
            <ode/>
          </friction>
        </surface>
      </collision>
      <collision name='base_link_fixed_joint_lump__hokuyo_link_2_collision_7'>
        <pose frame=''>0.08 -0.09 0.1 0 -0.1 -2.83319</pose>
        <geometry>
          <cylinder>
            <length>0.12</length>
            <radius>0.015</radius>
          </cylinder>
        </geometry>
        <surface>
          <contact>
            <ode/>
          </contact>
          <friction>
            <ode/>
          </friction>
        </surface>
      </collision>
      <collision name='base_link_fixed_joint_lump__imu_sensor_link_collision_8'>
        <pose frame=''>-0.1 0 0.05 0 -0 0</pose>
        <geometry>
          <box>
            <size>0.02 0.02 0.02</size>
          </box>
        </geometry>
        <surface>
          <contact>
            <ode/>
          </contact>
          <friction>
            <ode/>
          </friction>
        </surface>
      </collision>
      <visual name='base_link_fixed_joint_lump__chassis_visual'>
        <pose frame=''>0 0 0 0 -0 0</pose>
        <geometry>
          <cylinder>
            <length>0.08</length>
            <radius>0.17</radius>
          </cylinder>
        </geometry>
        <material>
          <script>
            <name>Gazebo/Yellow</name>
            <uri>file://media/materials/scripts/gazebo.material</uri>
          </script>
        </material>
      </visual>
      <visual name='base_link_fixed_joint_lump__left_axis_visual_1'>
        <pose frame=''>0 0.14 -0.02 -1.5708 0 0</pose>
        <geometry>
          <cylinder>
            <length>0.02</length>
            <radius>0.0025</radius>
          </cylinder>
        </geometry>
      </visual>
      <visual name='base_link_fixed_joint_lump__right_axis_visual_2'>
        <pose frame=''>0 -0.14 -0.02 -1.5708 0 0</pose>
        <geometry>
          <cylinder>
            <length>0.02</length>
            <radius>0.0025</radius>
          </cylinder>
        </geometry>
      </visual>
      <visual name='base_link_fixed_joint_lump__box_visual_3'>
        <pose frame=''>-0.1 0 0.25 0 -0 0</pose>
        <geometry>
          <box>
            <size>0.01 0.01 0.5</size>
          </box>
        </geometry>
      </visual>
      <visual name='base_link_fixed_joint_lump__camera_link_visual_4'>
        <pose frame=''>0.08 0 0.1 0 -0 0</pose>
        <geometry>
          <box>
            <size>0.02 0.08 0.11</size>
          </box>
        </geometry>
        <material>
          <script>
            <uri>__default__</uri>
            <name>__default__</name>
          </script>
        </material>
      </visual>
      <visual name='base_link_fixed_joint_lump__camera_up_link_visual_5'>
        <pose frame=''>-0.08 0 0.5 0 1.4 0</pose>
        <geometry>
          <box>
            <size>0.02 0.05 0.05</size>
          </box>
        </geometry>
        <material>
          <script>
            <uri>__default__</uri>
            <name>__default__</name>
          </script>
        </material>
      </visual>
      <visual name='base_link_fixed_joint_lump__hokuyo_link_visual_6'>
        <pose frame=''>0.08 0.09 0.1 0 -0.1 3.11</pose>
        <geometry>
          <cylinder>
            <length>0.12</length>
            <radius>0.015</radius>
          </cylinder>
        </geometry>
        <material>
          <script>
            <uri>__default__</uri>
            <name>__default__</name>
          </script>
        </material>
      </visual>
      <visual name='base_link_fixed_joint_lump__hokuyo_link_2_visual_7'>
        <pose frame=''>0.08 -0.09 0.1 0 -0.1 -2.83319</pose>
        <geometry>
          <cylinder>
            <length>0.12</length>
            <radius>0.015</radius>
          </cylinder>
        </geometry>
        <material>
          <script>
            <uri>__default__</uri>
            <name>__default__</name>
          </script>
        </material>
      </visual>
      <visual name='base_link_fixed_joint_lump__imu_sensor_link_visual_8'>
        <pose frame=''>-0.1 0 0.05 0 -0 0</pose>
        <geometry>
          <box>
            <size>0.02 0.02 0.02</size>
          </box>
        </geometry>
        <material>
          <script>
            <uri>__default__</uri>
            <name>__default__</name>
          </script>
        </material>
      </visual>
      <velocity_decay/>
      <sensor name='irobot_bumper_sensor' type='contact'>
        <always_on>1</always_on>
        <update_rate>100</update_rate>
        <contact>
          <collision>base_link_collision</collision>
          <topic>__default_topic__</topic>
        </contact>
        <plugin name='base_link_gazebo_ros_bumper_controller' filename='libgazebo_ros_bumper.so'>
          <alwaysOn>true</alwaysOn>
          <updateRate>100.0</updateRate>
          <bumperTopicName>irobot_bumper</bumperTopicName>
          <frameName>base_link</frameName>
        </plugin>
      </sensor>
      <velocity_decay/>
      <velocity_decay/>
      <velocity_decay/>
      <sensor name='camera' type='camera'>
        <update_rate>30</update_rate>
        <camera name='head'>
          <horizontal_fov>1.39626</horizontal_fov>
          <image>
            <width>640</width>
            <height>480</height>
            <format>R8G8B8</format>
          </image>
          <clip>
            <near>0.02</near>
            <far>300</far>
          </clip>
          <noise>
            <type>gaussian</type>
            <mean>0</mean>
            <stddev>0.007</stddev>
          </noise>
        </camera>
        <plugin name='camera_controller' filename='libgazebo_ros_camera.so'>
          <alwaysOn>true</alwaysOn>
          <updateRate>0.0</updateRate>
          <cameraName>iRobot/camera</cameraName>
          <imageTopicName>image_raw</imageTopicName>
          <cameraInfoTopicName>camera_info</cameraInfoTopicName>
          <frameName>camera_link</frameName>
          <hackBaseline>0.07</hackBaseline>
          <distortionK1>0.0</distortionK1>
          <distortionK2>0.0</distortionK2>
          <distortionK3>0.0</distortionK3>
          <distortionT1>0.0</distortionT1>
          <distortionT2>0.0</distortionT2>
        </plugin>
        <pose frame=''>0.08 0 0.1 0 -0 0</pose>
      </sensor>
      <velocity_decay/>
      <sensor name='camera' type='camera'>
        <update_rate>30</update_rate>
        <camera name='head'>
          <horizontal_fov>1.39626</horizontal_fov>
          <image>
            <width>640</width>
            <height>480</height>
            <format>R8G8B8</format>
          </image>
          <clip>
            <near>0.02</near>
            <far>300</far>
          </clip>
          <noise>
            <type>gaussian</type>
            <mean>0</mean>
            <stddev>0.007</stddev>
          </noise>
        </camera>
        <plugin name='camera_up_controller' filename='libgazebo_ros_camera.so'>
          <alwaysOn>true</alwaysOn>
          <updateRate>0.0</updateRate>
          <cameraName>iRobot/camera_up</cameraName>
          <imageTopicName>image_raw</imageTopicName>
          <cameraInfoTopicName>camera_info</cameraInfoTopicName>
          <frameName>camera_up_link</frameName>
          <hackBaseline>0.07</hackBaseline>
          <distortionK1>0.0</distortionK1>
          <distortionK2>0.0</distortionK2>
          <distortionK3>0.0</distortionK3>
          <distortionT1>0.0</distortionT1>
          <distortionT2>0.0</distortionT2>
        </plugin>
        <pose frame=''>-0.08 0 0.5 0 1.4 0</pose>
      </sensor>
      <velocity_decay/>
      <gravity>1</gravity>
      <sensor name='head_hokuyo_sensor' type='ray'>
        <visualize>1</visualize>
        <update_rate>40</update_rate>
        <ray>
          <scan>
            <horizontal>
              <samples>2</samples>
              <resolution>1</resolution>
              <min_angle>-3.14</min_angle>
              <max_angle>3.14</max_angle>
            </horizontal>
          </scan>
          <range>
            <min>0.2</min>
            <max>40</max>
            <resolution>0.025</resolution>
          </range>
          <noise>
            <type>gaussian</type>
            <mean>0</mean>
            <stddev>0</stddev>
          </noise>
        </ray>
        <plugin name='gazebo_ros_head_hokuyo_controller' filename='libgazebo_ros_laser.so'>
          <topicName>/laser_scan</topicName>
          <frameName>hokuyo_link</frameName>
        </plugin>
        <pose frame=''>0.08 0.09 0.1 0 -0.1 3.11</pose>
      </sensor>
      <gravity>1</gravity>
      <velocity_decay/>
      <gravity>1</gravity>
      <sensor name='head_hokuyo_sensor' type='ray'>
        <visualize>1</visualize>
        <update_rate>40</update_rate>
        <ray>
          <scan>
            <horizontal>
              <samples>2</samples>
              <resolution>1</resolution>
              <min_angle>-3.14</min_angle>
              <max_angle>3.14</max_angle>
            </horizontal>
          </scan>
          <range>
            <min>0.12</min>
            <max>3.5</max>
            <resolution>0.015</resolution>
          </range>
          <noise>
            <type>gaussian</type>
            <mean>0</mean>
            <stddev>0.01</stddev>
          </noise>
        </ray>
        <plugin name='gazebo_ros_head_hokuyo_2_controller' filename='libgazebo_ros_laser.so'>
          <topicName>/laser_scan_2</topicName>
          <frameName>hokuyo_link_2</frameName>
        </plugin>
        <pose frame=''>0.08 -0.09 0.1 0 -0.1 -2.83319</pose>
      </sensor>
      <gravity>1</gravity>
      <velocity_decay/>
      <gravity>1</gravity>
      <sensor name='imu_sensor' type='imu'>
        <always_on>1</always_on>
        <update_rate>1000</update_rate>
        <visualize>1</visualize>
        <topic>__default_topic__</topic>
        <plugin name='imu_plugin' filename='libgazebo_ros_imu_sensor.so'>
          <topicName>imu_data</topicName>
          <bodyName>imu_sensor_link</bodyName>
          <updateRateHZ>10.0</updateRateHZ>
          <gaussianNoise>0.0</gaussianNoise>
          <xyzOffset>0 0 0</xyzOffset>
          <rpyOffset>0 0 0</rpyOffset>
          <frameName>imu_sensor_link</frameName>
        </plugin>
        <pose frame=''>-0.1 0 0.05 0 -0 0</pose>
      </sensor>
    </link>
    <link name='left_wheel_link'>
      <pose frame=''>0 0.14 -0.02 0 -0 0</pose>
      <inertial>
        <pose frame=''>0 0.01 0 -1.5708 0 0</pose>
        <mass>0.5</mass>
        <inertia>
          <ixx>0.000129167</ixx>
          <ixy>0</ixy>
          <ixz>0</ixz>
          <iyy>0.000129167</iyy>
          <iyz>0</iyz>
          <izz>3.75e-05</izz>
        </inertia>
      </inertial>
      <collision name='left_wheel_link_collision'>
        <pose frame=''>0 0 0 -1.5708 0 0</pose>
        <geometry>
          <cylinder>
            <length>0.02</length>
            <radius>0.03</radius>
          </cylinder>
        </geometry>
        <surface>
          <contact>
            <ode>
              <kp>1e+07</kp>
              <kd>1</kd>
              <min_depth>0.0001</min_depth>
            </ode>
          </contact>
          <friction>
            <ode>
              <mu>50</mu>
              <mu2>10</mu2>
              <fdir1>1 0 0</fdir1>
            </ode>
          </friction>
        </surface>
        <max_contacts>1</max_contacts>
      </collision>
      <visual name='left_wheel_link_visual'>
        <pose frame=''>0 0 0 -1.5708 0 0</pose>
        <geometry>
          <cylinder>
            <length>0.02</length>
            <radius>0.03</radius>
          </cylinder>
        </geometry>
        <material>
          <script>
            <name>Gazebo/Grey</name>
            <uri>file://media/materials/scripts/gazebo.material</uri>
          </script>
        </material>
      </visual>
      <gravity>1</gravity>
      <velocity_decay/>
      <gravity>1</gravity>
    </link>
    <joint name='left_wheel_rot_joint' type='revolute'>
      <child>left_wheel_link</child>
      <parent>base_link</parent>
      <axis>
        <xyz>0 1 0</xyz>
        <limit>
          <lower>-1e+16</lower>
          <upper>1e+16</upper>
        </limit>
        <dynamics>
          <spring_reference>0</spring_reference>
          <spring_stiffness>0</spring_stiffness>
        </dynamics>
        <use_parent_model_frame>1</use_parent_model_frame>
      </axis>
    </joint>
    <link name='right_wheel_link'>
      <pose frame=''>0 -0.14 -0.02 0 -0 0</pose>
      <inertial>
        <pose frame=''>0 0.01 0 -1.5708 0 0</pose>
        <mass>0.5</mass>
        <inertia>
          <ixx>0.000129167</ixx>
          <ixy>0</ixy>
          <ixz>0</ixz>
          <iyy>0.000129167</iyy>
          <iyz>0</iyz>
          <izz>3.75e-05</izz>
        </inertia>
      </inertial>
      <collision name='right_wheel_link_collision'>
        <pose frame=''>0 0 0 -1.5708 0 0</pose>
        <geometry>
          <cylinder>
            <length>0.02</length>
            <radius>0.03</radius>
          </cylinder>
        </geometry>
        <surface>
          <contact>
            <ode>
              <kp>1e+07</kp>
              <kd>1</kd>
              <min_depth>0.0001</min_depth>
            </ode>
          </contact>
          <friction>
            <ode>
              <mu>50</mu>
              <mu2>10</mu2>
              <fdir1>1 0 0</fdir1>
            </ode>
          </friction>
        </surface>
        <max_contacts>1</max_contacts>
      </collision>
      <visual name='right_wheel_link_visual'>
        <pose frame=''>0 0 0 -1.5708 0 0</pose>
        <geometry>
          <cylinder>
            <length>0.02</length>
            <radius>0.03</radius>
          </cylinder>
        </geometry>
        <material>
          <script>
            <name>Gazebo/Grey</name>
            <uri>file://media/materials/scripts/gazebo.material</uri>
          </script>
        </material>
      </visual>
      <gravity>1</gravity>
      <velocity_decay/>
      <gravity>1</gravity>
    </link>
    <joint name='right_wheel_rot_joint' type='revolute'>
      <child>right_wheel_link</child>
      <parent>base_link</parent>
      <axis>
        <xyz>0 1 0</xyz>
        <limit>
          <lower>-1e+16</lower>
          <upper>1e+16</upper>
        </limit>
        <dynamics>
          <spring_reference>0</spring_reference>
          <spring_stiffness>0</spring_stiffness>
        </dynamics>
        <use_parent_model_frame>1</use_parent_model_frame>
      </axis>
    </joint>
    <link name='sphere1'>
      <pose frame=''>0.14 0 -0.04 0 -0 0</pose>
      <inertial>
        <pose frame=''>0 0 0 0 -0 0</pose>
        <mass>0.3</mass>
        <inertia>
          <ixx>1.2e-05</ixx>
          <ixy>0</ixy>
          <ixz>0</ixz>
          <iyy>1.2e-05</iyy>
          <iyz>0</iyz>
          <izz>1.2e-05</izz>
        </inertia>
      </inertial>
      <collision name='sphere1_collision'>
        <pose frame=''>0 0 0 0 -0 0</pose>
        <geometry>
          <sphere>
            <radius>0.01</radius>
          </sphere>
        </geometry>
        <surface>
          <contact>
            <ode>
              <kp>1e+07</kp>
              <kd>1</kd>
              <min_depth>0.0001</min_depth>
            </ode>
          </contact>
          <friction>
            <ode>
              <mu>0</mu>
              <mu2>0</mu2>
              <fdir1>1 0 0</fdir1>
            </ode>
          </friction>
        </surface>
        <max_contacts>1</max_contacts>
      </collision>
      <visual name='sphere1_visual'>
        <pose frame=''>0 0 0 0 -0 0</pose>
        <geometry>
          <sphere>
            <radius>0.01</radius>
          </sphere>
        </geometry>
        <material>
          <script>
            <name>Gazebo/Grey</name>
            <uri>file://media/materials/scripts/gazebo.material</uri>
          </script>
        </material>
      </visual>
      <gravity>1</gravity>
      <velocity_decay/>
      <gravity>1</gravity>
    </link>
    <joint name='sphere_joint1' type='revolute'>
      <child>sphere1</child>
      <parent>base_link</parent>
      <axis>
        <xyz>0 0 1</xyz>
        <limit>
          <lower>0</lower>
          <upper>0</upper>
          <effort>100</effort>
          <velocity>100</velocity>
        </limit>
        <dynamics>
          <spring_reference>0</spring_reference>
          <spring_stiffness>0</spring_stiffness>
        </dynamics>
        <use_parent_model_frame>1</use_parent_model_frame>
      </axis>
    </joint>
    <link name='sphere2'>
      <pose frame=''>-0.14 0 -0.04 0 -0 0</pose>
      <inertial>
        <pose frame=''>0 0 0 0 -0 0</pose>
        <mass>0.3</mass>
        <inertia>
          <ixx>1.2e-05</ixx>
          <ixy>0</ixy>
          <ixz>0</ixz>
          <iyy>1.2e-05</iyy>
          <iyz>0</iyz>
          <izz>1.2e-05</izz>
        </inertia>
      </inertial>
      <collision name='sphere2_collision'>
        <pose frame=''>0 0 0 0 -0 0</pose>
        <geometry>
          <sphere>
            <radius>0.01</radius>
          </sphere>
        </geometry>
        <surface>
          <contact>
            <ode>
              <kp>1e+07</kp>
              <kd>1</kd>
              <min_depth>0.0001</min_depth>
            </ode>
          </contact>
          <friction>
            <ode>
              <mu>0</mu>
              <mu2>0</mu2>
              <fdir1>1 0 0</fdir1>
            </ode>
          </friction>
        </surface>
        <max_contacts>1</max_contacts>
      </collision>
      <visual name='sphere2_visual'>
        <pose frame=''>0 0 0 0 -0 0</pose>
        <geometry>
          <sphere>
            <radius>0.01</radius>
          </sphere>
        </geometry>
        <material>
          <script>
            <name>Gazebo/Grey</name>
            <uri>file://media/materials/scripts/gazebo.material</uri>
          </script>
        </material>
      </visual>
      <gravity>1</gravity>
      <velocity_decay/>
      <gravity>1</gravity>
    </link>
    <joint name='sphere_joint2' type='revolute'>
      <child>sphere2</child>
      <parent>base_link</parent>
      <axis>
        <xyz>0 0 1</xyz>
        <limit>
          <lower>0</lower>
          <upper>0</upper>
          <effort>100</effort>
          <velocity>100</velocity>
        </limit>
        <dynamics>
          <spring_reference>0</spring_reference>
          <spring_stiffness>0</spring_stiffness>
        </dynamics>
        <use_parent_model_frame>1</use_parent_model_frame>
      </axis>
    </joint>
    <static>0</static>
    <plugin name='differential_drive_controller' filename='libgazebo_ros_diff_drive.so'>
      <rosDebugLevel>Debug</rosDebugLevel>
      <publishWheelTF>false</publishWheelTF>
      <legacyMode>false</legacyMode>
      <publishWheelJointState>true</publishWheelJointState>
      <alwaysOn>true</alwaysOn>
      <leftJoint>left_wheel_rot_joint</leftJoint>
      <rightJoint>right_wheel_rot_joint</rightJoint>
      <wheelSeparation>0.28</wheelSeparation>
      <wheelDiameter>0.06</wheelDiameter>
      <torque>20</torque>
      <wheelAcceleration>1.8</wheelAcceleration>
      <commandTopic>cmd_vel</commandTopic>
      <odometryTopic>odom</odometryTopic>
      <odometryFrame>odom</odometryFrame>
      <odometrySource>encoder</odometrySource>
      <robotBaseFrame>base_link</robotBaseFrame>
      <updateRate>10.0</updateRate>
    </plugin>
    <plugin name='joint_state_publisher' filename='libgazebo_ros_joint_state_publisher.so'>
      <jointName>left_wheel_rot_joint, right_wheel_rot_joint</jointName>
      <updateRate>10.0</updateRate>
      <alwaysOn>true</alwaysOn>
    </plugin>
    <plugin name='imu_plugin' filename='libgazebo_ros_imu.so'>
      <bodyName>base_link</bodyName>
      <updateRate>100.0</updateRate>
      <topicName>imu_data</topicName>
      <serviceName>imu_service</serviceName>
      <gaussianNoise>0.1</gaussianNoise>
      <frameName>base_link</frameName>
      <xyzOffset>0.1 0 -0.05</xyzOffset>
      <rpyOffset>0 -0 0</rpyOffset>
    </plugin>
  </model>
</sdf>
